<?xml version="1.0"?>
<robot name="robot_arm">
  <link name="base_link">
    <visual>
      <geometry>
        <mesh filename="package://urdf01rviz/myrobot/meshes/arm_baselink.stl" scale="0.001 0.001 0.001"/>
      </geometry>
      <material name="LightGrey">
        <color rgba="0.2 0.3 0.4 1.0"/>
      </material>
      <origin xyz="0.0 0.0 0" rpy="0.0 0.0 0"/>
    </visual>
  </link>
  <link name="link1">
   <visual>
      <geometry>
        <mesh filename="package://urdf01rviz/myrobot/meshes/arm_link1.stl" scale="0.001 0.001 0.001"/>
      </geometry>
      <material name="LightGrey">
        <color rgba="0.2 0.3 0.4 1.0"/>
      </material>
      <origin xyz="0.0 0.0 -0.0404" rpy="0.0 0.0 -1.5707963267948966"/>
    </visual>
  </link>
  <joint name="joint1" type="revolute">
    <parent link="base_link"/>
    <child link="link1"/>
    <origin xyz="0 -0.0 0.1184" rpy="0.0 0 0.0"/>
    <axis xyz="0 0 1"/>
    <limit effort="100" velocity="1.0" lower="-3.14" upper="3.14"/>
  </joint>
  <link name="link2">
     <visual>
      <geometry>
        <mesh filename="package://urdf01rviz/myrobot/meshes/arm_link2.stl" scale="0.001 0.001 0.001"/>
      </geometry>
      <material name="LightGrey">
        <color rgba="0.2 0.3 0.4 1.0"/>
      </material>
      <origin xyz="0.0 0.0 0" rpy="0.785 -1.5707963267948966 3.1415926"/>
    </visual>
  </link>
  <joint name="joint2" type="revolute">
    <parent link="link1"/>
    <child link="link2"/>
    <origin xyz="0 -0.0346 2.118638962524921e-15" rpy="1.5707963267948966 -1.5707963267948966 0 "/>
    <axis xyz="0 0 1"/>
    <limit effort="100" velocity="1.0" lower="-3.14" upper="3.14"/>
  </joint>
  <link name="link3">
       <visual>
      <geometry>
        <mesh filename="package://urdf01rviz/myrobot/meshes/arm_link3.stl" scale="0.001 0.001 0.001"/>
      </geometry>
      <material name="LightGrey">
        <color rgba="0.2 0.3 0.4 1.0"/>
      </material>
      <origin xyz="0.0 0.0 0" rpy="0.0 0.0 0"/>
    </visual>
  </link>
  

  <joint name="joint3" type="revolute">
    <parent link="link2"/>
    <child link="link3"/>
    <origin xyz="0.25 0.0 -0.02335" rpy="0.0 0 0.0"/>
    <axis xyz="0 0 1"/>
    <limit effort="100" velocity="1.0" lower="-3.14" upper="3.14"/>
  </joint>
  <link name="link4">
       <visual>
      <geometry>
        <mesh filename="package://urdf01rviz/myrobot/meshes/arm_link4.stl" scale="0.001 0.001 0.001"/>
      </geometry>
      <material name="LightGrey">
        <color rgba="0.2 0.3 0.4 1.0"/>
      </material>
      <origin xyz="0.0 0.0 0" rpy="0.0 0.0 0"/>
    </visual>
  </link>
  <joint name="joint4" type="revolute">
    <parent link="link3"/>
    <child link="link4"/>
    <origin xyz="0.06 -0.22605 1.384157044736296e-14" rpy="1.5707963267948966 0 0.0"/>
    <axis xyz="0 0 1"/>
    <limit effort="100" velocity="1.0" lower="-3.14" upper="3.14"/>
  </joint>
  <link name="link5">
       <visual>
      <geometry>
        <mesh filename="package://urdf01rviz/myrobot/meshes/arm_link5.stl" scale="0.001 0.001 0.001"/>
      </geometry>
      <material name="LightGrey">
        <color rgba="0.2 0.3 0.4 1.0"/>
      </material>
      <origin xyz="0.0 0.07725 0" rpy="0.0 0.0 0"/>
    </visual>
  </link>
  <joint name="joint5" type="revolute">
    <parent link="link4"/>
    <child link="link5"/>
    <origin xyz="0 0.0 0.0" rpy="1.5707963267948966 0 0"/>
    <axis xyz="0 0 1"/>
    <limit effort="100" velocity="1.0" lower="-3.14" upper="3.14"/>
  </joint>
  <link name="link6"/>
  <joint name="joint6" type="revolute">
    <parent link="link5"/>
    <child link="link6"/>
    <origin xyz="0 0.07725 0.0" rpy="-1.5707963267948966 1.5707963267948966 0 "/>
    <axis xyz="0 0 1"/>
    <limit effort="100" velocity="1.0" lower="-3.14" upper="3.14"/>
  </joint>
</robot>